WARNING  urllib3.connectionpool:connectionpool.py:812 Retrying (Retry(total=2, connect=None, read=None, redirect=None, status=None)) after connection broken by 'NewConnectionError('<urllib3.connection.HTTPConnection object at 0x110309030>: Failed to establish a new connection: [Errno 8] nodename nor servname provided, or not known')': /wd/hub/session
WARNING  urllib3.connectionpool:connectionpool.py:812 Retrying (Retry(total=1, connect=None, read=None, redirect=None, status=None)) after connection broken by 'NewConnectionError('<urllib3.connection.HTTPConnection object at 0x1103089d0>: Failed to establish a new connection: [Errno 8] nodename nor servname provided, or not known')': /wd/hub/session
WARNING  urllib3.connectionpool:connectionpool.py:812 Retrying (Retry(total=0, connect=None, read=None, redirect=None, status=None)) after connection broken by 'NewConnectionError('<urllib3.connection.HTTPConnection object at 0x110308250>: Failed to establish a new connection: [Errno 8] nodename nor servname provided, or not known')': /wd/hub/session